<?xml version='1.0'?>

<robot name="my_robot" xmlns:xacro="http://www.ros.org/wiki/xacro">
	<xacro:include filename="$(find my_robot)/urdf/my_robot.gazebo" />
  <link name="robot_footprint"></link>

  <joint name="robot_footprint_joint" type="fixed">
    <origin xyz="0 0 0" rpy="0 0 0" />
    <parent link="robot_footprint"/>
    <child link="chassis" />
  </joint>

  <link name='chassis'>
    <pose>0 0 0.1 0 0 0</pose>

    <inertial>
      <mass value="15.0"/>
      <origin xyz="0.0 0 0" rpy=" 0 0 0"/>
      <inertia
          ixx="0.1" ixy="0" ixz="0"
          iyy="0.1" iyz="0"
          izz="0.1"
      />
    </inertial>

    <collision name='collision'>
      <origin xyz="0 0 0" rpy=" 0 0 0"/> 
      <geometry>
        <box size=".4 .2 .1"/>
      </geometry>
    </collision>

    <visual name='chassis_visual'>
      <origin xyz="0 0 0" rpy=" 0 0 0"/>
      <geometry>
        <box size=".4 .2 .1"/>
      </geometry>
    </visual>


    <collision name='back_caster_collision'>
      <origin xyz="-0.15 0 -0.05" rpy=" 0 0 0"/>
      <geometry>
        <sphere radius="0.0499"/>
      </geometry>
    </collision>

    <visual name='back_caster_visual'>
      <origin xyz="-0.15 0 -0.05" rpy=" 0 0 0"/>
      <geometry>
        <sphere radius="0.05"/>
      </geometry>
    </visual>

    <collision name='front_caster_collision'>
      <origin xyz="0.15 0 -0.05" rpy=" 0 0 0"/>
      <geometry>
        <sphere radius="0.0499"/>
      </geometry>
    </collision>

    <visual name='front_caster_visual'>
      <origin xyz="0.15 0 -0.05" rpy=" 0 0 0"/>
      <geometry>
        <sphere radius="0.05"/>
      </geometry>
    </visual>

  </link>
  
  <link name='left_wheel'>
		<visual>
			<origin xyz="0 0 0" rpy="0 1.5707 1.5707"/>
			<geometry>
				<cylinder radius="0.1" length="0.05"/>
			</geometry>
		</visual>

		<collision>
			<origin xyz="0 0 0" rpy="0 1.5707 1.5707"/>
			<geometry>
				<cylinder radius="0.1" length="0.05"/>
			</geometry>
		</collision>

		<inertial>
			<mass value="5.0"/>
      <origin xyz="0.0 0 0" rpy=" 0 1.5707 1.5707"/>
      <inertia
          ixx="0.1" ixy="0" ixz="0"
          iyy="0.1" iyz="0"
          izz="0.1"
      />
		</inertial>
	</link>

  <joint type="continuous" name="left_wheel_hinge">
		<origin xyz="0 0.15 0" rpy="0 0 0"/>
		<child link="left_wheel"/>
		<parent link="chassis"/>
		<axis xyz="0 1 0" rpy="0 0 0"/>
		<limit effort="10000" velocity="1000"/>
		<dynamics damping="1.0" friction="1.0"/>
	</joint>

	<link name='right_wheel'>
		<visual>
			<origin xyz="0 0 0" rpy="0 1.5707 1.5707"/>
			<geometry>
				<cylinder radius="0.1" length="0.05"/>
			</geometry>
		</visual>

		<collision>
			<origin xyz="0 0 0" rpy="0 1.5707 1.5707"/>
			<geometry>
				<cylinder radius="0.1" length="0.05"/>
			</geometry>
		</collision>

		<inertial>
			<mass value="5.0"/>
      <origin xyz="0.0 0 0" rpy=" 0 1.5707 1.5707"/>
      <inertia
          ixx="0.1" ixy="0" ixz="0"
          iyy="0.1" iyz="0"
          izz="0.1"
      />
		</inertial>
	</link>
	
	<joint type="continuous" name="right_wheel_hinge">
		<origin xyz="0 -0.15 0" rpy="0 0 0"/>
		<child link="right_wheel"/>
		<parent link="chassis"/>
		<axis xyz="0 1 0" rpy="0 0 0"/>
		<limit effort="10000" velocity="1000"/>
		<dynamics damping="1.0" friction="1.0"/>
	</joint>
	
	<link name='camera_link'>
		<visual>
			<origin xyz="0 0 0" rpy="0 0 0"/>
			<geometry>
				<box size="0.05 0.05 0.05"/>
			</geometry>
		</visual>

		<collision>
			<origin xyz="0 0 0" rpy="0 0 0"/>
			<geometry>
				<box size="0.05 0.05 0.05"/>
			</geometry>
		</collision>

		<inertial>
			<mass value="0.1"/>
      <origin xyz="0 0 0" rpy=" 0 0 0"/>
      <inertia
          ixx="1e-6" ixy="0" ixz="0"
          iyy="1e-6" iyz="0"
          izz="1e-6"
      />
		</inertial>
	</link>



	<joint type='fixed' name='camera_joint'>
		<origin xyz="0.2 0 0" rpy="0 0 0"/>
		<child link="camera_link"/>
		<parent link="chassis"/>
		<axis xyz="0 1 0" rpy="0 0 0"/>
	</joint>

	<joint name="camera_optical_joint" type="fixed">
		<origin xyz="0 0 0" rpy="-1.5707 0 -1.5707"/>
		<parent link="camera_link"/>
		<child link="camera_link_optical"/>
  	</joint>

  	<link name="camera_link_optical">
  	</link>

	
	<link name='hokuyo'>
		<visual>
			<origin xyz="0 0 0" rpy="0 0 0"/>
			<geometry>
				<mesh filename="package://my_robot/meshes/hokuyo.dae"/>
			</geometry>
		</visual>

		<collision>
			<origin xyz="0 0 0" rpy="0 0 0"/>
			<geometry>
				<box size="0.1 0.1 0.1"/>
			</geometry>
		</collision>

		<inertial>
			<mass value="1e-5"/>
			<origin xyz="0 0 0" rpy="0 0 0"/>
			<inertia
				ixx="1e-6" ixy="0" ixz="0"
				iyy="1e-6" iyz="0"
				izz="1e-6"
			/>
		</inertial>
	</link>
	
	<joint type='fixed' name='hokuyo_joint'>
		<origin xyz="0.15 0 0.1" rpy="0 0 0"/>
		<child link="hokuyo"/>
		<parent link="chassis"/>
		<axis xyz="0 1 0" rpy="0 0 0"/>
	</joint>

	<!-- RGBD Camera -->
  	<!--<gazebo reference="camera_link">
		<sensor type="depth" name="camera1">
		    <always_on>1</always_on>
		    <update_rate>20.0</update_rate>
		    <visualize>true</visualize>             
		    <camera>
		        <horizontal_fov>1.047</horizontal_fov>  
		        <image>
		            <width>640</width>
		            <height>480</height>
		            <format>R8G8B8</format>
		        </image>
		        <depth_camera>

		        </depth_camera>
		        <clip>
		            <near>0.1</near>
		            <far>20</far>
		        </clip>
		    </camera>
		     <plugin name="camera_controller" filename="libgazebo_ros_openni_kinect.so">
		        <alwaysOn>true</alwaysOn>
		        <updateRate>10.0</updateRate>
		        <cameraName>camera</cameraName>
		        <frameName>camera_link_optical</frameName>                   
		        <imageTopicName>rgb/image_raw</imageTopicName>
		        <depthImageTopicName>depth/image_raw</depthImageTopicName>
		        <pointCloudTopicName>depth/points</pointCloudTopicName>
		        <cameraInfoTopicName>rgb/camera_info</cameraInfoTopicName>              
		        <depthImageCameraInfoTopicName>depth/camera_info</depthImageCameraInfoTopicName>            
		        <pointCloudCutoff>0.4</pointCloudCutoff>                
		            <hackBaseline>0.07</hackBaseline>
		            <distortionK1>0.0</distortionK1>
		            <distortionK2>0.0</distortionK2>
		            <distortionK3>0.0</distortionK3>
		            <distortionT1>0.0</distortionT1>
		            <distortionT2>0.0</distortionT2>
		        <CxPrime>0.0</CxPrime>
		        <Cx>0.0</Cx>
		        <Cy>0.0</Cy>
		        <focalLength>0.0</focalLength>
		        </plugin>
		</sensor>
  	</gazebo>-->


	<gazebo reference="left_wheel">
		<material>Gazebo/Green</material>
	</gazebo>
	
	<gazebo reference="right_wheel">
		<material>Gazebo/Green</material>
	</gazebo>
	
	<gazebo reference="chassis">
		<material>Gazebo/Red</material>
	</gazebo>
	
</robot>

